2024-12-22 09:03:52,986 - test_finance - ERROR - Exception occured in <function measure_time_async.<locals>.inner at 0x7a82a715a7a0> with kargs={'file_path': 'data/RIB maman.pdf'}: cannot unpack non-iterable NoneType object 
Traceback (most recent call last):
  File "/home/jacques/works/RevolutionAI/Core/Libs-python/src/lxf/services/try_safe.py", line 23, in try_safe_execute_asyncio
    result= asyncio.run(func(**kargs))
            ^^^^^^^^^^^^^^^^^^^^^^^^^^
  File "/usr/lib/python3.12/asyncio/runners.py", line 194, in run
    return runner.run(main)
           ^^^^^^^^^^^^^^^^
  File "/usr/lib/python3.12/asyncio/runners.py", line 118, in run
    return self._loop.run_until_complete(task)
           ^^^^^^^^^^^^^^^^^^^^^^^^^^^^^^^^^^^
  File "/usr/lib/python3.12/asyncio/base_events.py", line 687, in run_until_complete
    return future.result()
           ^^^^^^^^^^^^^^^
  File "/home/jacques/works/RevolutionAI/Core/Libs-python/src/lxf/services/measure_time.py", line 26, in inner
    result = await func(*arg,**kwargs)
             ^^^^^^^^^^^^^^^^^^^^^^^^^
  File "/home/jacques/works/RevolutionAI/Core/Libs-python/src/test_finance.py", line 34, in do_test_classifier
    return await get_classification(file_name=file_path)
           ^^^^^^^^^^^^^^^^^^^^^^^^^^^^^^^^^^^^^^^^^^^^^
  File "/home/jacques/works/RevolutionAI/Core/Libs-python/src/lxf/services/measure_time.py", line 26, in inner
    result = await func(*arg,**kwargs)
             ^^^^^^^^^^^^^^^^^^^^^^^^^
  File "/home/jacques/works/RevolutionAI/Core/Libs-python/src/lxf/ai/classification/classifier.py", line 38, in get_classification
    result,_ = await try_safe_execute_async(logger,get_text_and_tables_from_pdf, filename=file_name,extract_tables=False,max_pages=max_pages)
    ^^^^^^^^
TypeError: cannot unpack non-iterable NoneType object
2024-12-22 09:05:11,051 - test_finance - ERROR - Exception occured in <function measure_time_async.<locals>.inner at 0x758264b32840> with kargs={'file_path': 'data/RIB mamam.pdf'}: cannot unpack non-iterable NoneType object 
Traceback (most recent call last):
  File "/home/jacques/works/RevolutionAI/Core/Libs-python/src/lxf/services/try_safe.py", line 23, in try_safe_execute_asyncio
    result= asyncio.run(func(**kargs))
            ^^^^^^^^^^^^^^^^^^^^^^^^^^
  File "/usr/lib/python3.12/asyncio/runners.py", line 194, in run
    return runner.run(main)
           ^^^^^^^^^^^^^^^^
  File "/usr/lib/python3.12/asyncio/runners.py", line 118, in run
    return self._loop.run_until_complete(task)
           ^^^^^^^^^^^^^^^^^^^^^^^^^^^^^^^^^^^
  File "/usr/lib/python3.12/asyncio/base_events.py", line 687, in run_until_complete
    return future.result()
           ^^^^^^^^^^^^^^^
  File "/home/jacques/works/RevolutionAI/Core/Libs-python/src/lxf/services/measure_time.py", line 26, in inner
    result = await func(*arg,**kwargs)
             ^^^^^^^^^^^^^^^^^^^^^^^^^
  File "/home/jacques/works/RevolutionAI/Core/Libs-python/src/test_finance.py", line 34, in do_test_classifier
    return await get_classification(file_name=file_path)
           ^^^^^^^^^^^^^^^^^^^^^^^^^^^^^^^^^^^^^^^^^^^^^
  File "/home/jacques/works/RevolutionAI/Core/Libs-python/src/lxf/services/measure_time.py", line 26, in inner
    result = await func(*arg,**kwargs)
             ^^^^^^^^^^^^^^^^^^^^^^^^^
  File "/home/jacques/works/RevolutionAI/Core/Libs-python/src/lxf/ai/classification/classifier.py", line 38, in get_classification
    result,_ = await try_safe_execute_async(logger,get_text_and_tables_from_pdf, filename=file_name,extract_tables=False,max_pages=max_pages)
    ^^^^^^^^
TypeError: cannot unpack non-iterable NoneType object
2024-12-22 09:13:45,768 - test_finance - ERROR - Exception occured in <function measure_time_async.<locals>.inner at 0x7aa5ccd5e700> with kargs={'file_path': 'data/RIB_Jacqueline.pdf'}: BaseProcess.__init__() got an unexpected keyword argument 'input_pdf' 
Traceback (most recent call last):
  File "/home/jacques/works/RevolutionAI/Core/Libs-python/src/lxf/services/try_safe.py", line 23, in try_safe_execute_asyncio
    result= asyncio.run(func(**kargs))
            ^^^^^^^^^^^^^^^^^^^^^^^^^^
  File "/usr/lib/python3.12/asyncio/runners.py", line 194, in run
    return runner.run(main)
           ^^^^^^^^^^^^^^^^
  File "/usr/lib/python3.12/asyncio/runners.py", line 118, in run
    return self._loop.run_until_complete(task)
           ^^^^^^^^^^^^^^^^^^^^^^^^^^^^^^^^^^^
  File "/usr/lib/python3.12/asyncio/base_events.py", line 687, in run_until_complete
    return future.result()
           ^^^^^^^^^^^^^^^
  File "/home/jacques/works/RevolutionAI/Core/Libs-python/src/lxf/services/measure_time.py", line 26, in inner
    result = await func(*arg,**kwargs)
             ^^^^^^^^^^^^^^^^^^^^^^^^^
  File "/home/jacques/works/RevolutionAI/Core/Libs-python/src/test_finance.py", line 34, in do_test_classifier
    return await get_classification(file_name=file_path)
           ^^^^^^^^^^^^^^^^^^^^^^^^^^^^^^^^^^^^^^^^^^^^^
  File "/home/jacques/works/RevolutionAI/Core/Libs-python/src/lxf/services/measure_time.py", line 26, in inner
    result = await func(*arg,**kwargs)
             ^^^^^^^^^^^^^^^^^^^^^^^^^
  File "/home/jacques/works/RevolutionAI/Core/Libs-python/src/lxf/ai/classification/classifier.py", line 49, in get_classification
    p=Process(target=do_ocr,input_pdf=file_name,output_pdf=output_filename)
      ^^^^^^^^^^^^^^^^^^^^^^^^^^^^^^^^^^^^^^^^^^^^^^^^^^^^^^^^^^^^^^^^^^^^^
TypeError: BaseProcess.__init__() got an unexpected keyword argument 'input_pdf'
2024-12-22 09:22:57,447 - test_finance - ERROR - Exception occured in <function measure_time_async.<locals>.inner at 0x7698102be840> with kargs={'file_path': 'data/RIB_Jacqueline.pdf'}: too many values to unpack (expected 1) 
Traceback (most recent call last):
  File "/home/jacques/works/RevolutionAI/Core/Libs-python/src/lxf/services/try_safe.py", line 23, in try_safe_execute_asyncio
    result= asyncio.run(func(**kargs))
            ^^^^^^^^^^^^^^^^^^^^^^^^^^
  File "/usr/lib/python3.12/asyncio/runners.py", line 194, in run
    return runner.run(main)
           ^^^^^^^^^^^^^^^^
  File "/usr/lib/python3.12/asyncio/runners.py", line 118, in run
    return self._loop.run_until_complete(task)
           ^^^^^^^^^^^^^^^^^^^^^^^^^^^^^^^^^^^
  File "/usr/lib/python3.12/asyncio/base_events.py", line 687, in run_until_complete
    return future.result()
           ^^^^^^^^^^^^^^^
  File "/home/jacques/works/RevolutionAI/Core/Libs-python/src/lxf/services/measure_time.py", line 26, in inner
    result = await func(*arg,**kwargs)
             ^^^^^^^^^^^^^^^^^^^^^^^^^
  File "/home/jacques/works/RevolutionAI/Core/Libs-python/src/test_finance.py", line 34, in do_test_classifier
    return await get_classification(file_name=file_path)
           ^^^^^^^^^^^^^^^^^^^^^^^^^^^^^^^^^^^^^^^^^^^^^
  File "/home/jacques/works/RevolutionAI/Core/Libs-python/src/lxf/services/measure_time.py", line 26, in inner
    result = await func(*arg,**kwargs)
             ^^^^^^^^^^^^^^^^^^^^^^^^^
  File "/home/jacques/works/RevolutionAI/Core/Libs-python/src/lxf/ai/classification/classifier.py", line 53, in get_classification
    result, = await try_safe_execute_async(logger,get_text_and_tables_from_pdf, filename=output_filename,extract_tables=False,max_pages=max_pages)
    ^^^^^^^
ValueError: too many values to unpack (expected 1)
